fn test() {
  throw 'Test exception'
}

try {
  writeln('start')
  test()
  writeln('finish')
} catch(e) {
  writeln('Exception: ', e)
}
